Workbook

Sheet Turnip
A1: Week | B1: Date | C1: BuyPrice (Range is 90 - 110 Bells Per Turnip) | D1: Turnips (Given inventory = 1000) | E1: SellPrice (Max Sell Price 660 Bells per Turnip) | F1: ProfitPerTurnip | G1: % profit | H1: Sub_Total_Of_All | I1: Best_Sell_Price | J1: Sub_Total | K1: Winning_Week? | M1: Avg_Profit_Per_Turnip
A2: 1 | B2: 43906 | C2: 95 | D2: 1000 | E2: 110 | F2: =E2 - C2 -> 15 | G2: =(E2-C2)/(C2) -> 0.15789474 | H2: =E2 * D2 - C2 * D2 -> 15000 | I2: =MAX(E2:E7) -> 110 | J2: =(I2 *D2) - (C2 *D2) -> 15000 | K2: =IF(J2 > 0, "Profit This Week", "Negative This Week") -> Profit This Week | M2: =AVERAGE(F2:F84) -> 36.291667
A3: 1 | B3: 43907 | C3: 95 | D3: 1000 | E3: 105 | F3: =E3 - C3 -> 10 | G3: =(E3-C3)/(C3) -> 0.10526316 | H3: =E3 * D3 - C3 * D3 -> 10000
A4: 1 | B4: 43908 | C4: 95 | D4: 1000 | E4: 98 | F4: =E4 - C4 -> 3 | G4: =(E4-C4)/(C4) -> 0.031578947 | H4: =E4 * D4 - C4 * D4 -> 3000 | M4: Min_Profit_Per_Turnip
A5: 1 | B5: 43909 | C5: 95 | D5: 1000 | E5: 90 | F5: =E5 - C5 -> -5 | G5: =(E5-C5)/(C5) -> -0.052631579 | H5: =E5 * D5 - C5 * D5 -> -5000 | M5: =MIN(F2:F84) -> -32
A6: 1 | B6: 43910 | C6: 95 | D6: 1000 | E6: 85 | F6: =E6 - C6 -> -10 | G6: =(E6-C6)/(C6) -> -0.10526316 | H6: =E6 * D6 - C6 * D6 -> -10000
A7: 1 | B7: 43911 | C7: 95 | D7: 1000 | E7: 80 | F7: =E7 - C7 -> -15 | G7: =(E7-C7)/(C7) -> -0.15789474 | H7: =E7 * D7 - C7 * D7 -> -15000 | M7: Max_Profit_Per_Turnip
H8: =E8 * D8 - C8 * D8 -> 0 | M8: =MAX(F2:F84) -> 460
A9: 2 | B9: 43913 | C9: 92 | D9: 1000 | E9: 88 | F9: =E9 - C9 -> -4 | G9: =(E9-C9)/(C9) -> -0.043478261 | H9: =E9 * D9 - C9 * D9 -> -4000 | I9: =MAX(E9:E14) -> 88 | J9: =(I9 *D9) - (C9 *D9) -> -4000 | K9: =IF(J9 > 0, "Profit This Week", "Negative This Week") -> Negative This Week
A10: 2 | B10: 43914 | C10: 92 | D10: 1000 | E10: 82 | F10: =E10 - C10 -> -10 | G10: =(E10-C10)/(C10) -> -0.10869565 | H10: =E10 * D10 - C10 * D10 -> -10000 | M10: Standard_Deviation_Best_Sell | O10: Average_Plus_3_Std
A11: 2 | B11: 43915 | C11: 92 | D11: 1000 | E11: 76 | F11: =E11 - C11 -> -16 | G11: =(E11-C11)/(C11) -> -0.17391304 | H11: =E11 * D11 - C11 * D11 -> -16000 | M11: =ROUND(STDEV(I2:I79), 2) -> 189.98 | O11: =M2 + 3 *M20 -> 352.20741
A12: 2 | B12: 43916 | C12: 92 | D12: 1000 | E12: 70 | F12: =E12 - C12 -> -22 | G12: =(E12-C12)/(C12) -> -0.23913043 | H12: =E12 * D12 - C12 * D12 -> -22000
A13: 2 | B13: 43917 | C13: 92 | D13: 1000 | E13: 65 | F13: =E13 - C13 -> -27 | G13: =(E13-C13)/(C13) -> -0.29347826 | H13: =E13 * D13 - C13 * D13 -> -27000 | M13: Sum_Of_Bells with 25% or higher profit | O13: Average_Minus_3_Std
A14: 2 | B14: 43918 | C14: 92 | D14: 1000 | E14: 60 | F14: =E14 - C14 -> -32 | G14: =(E14-C14)/(C14) -> -0.34782609 | H14: =E14 * D14 - C14 * D14 -> -32000 | M14: =SUMIF(G2:G84, ">="&0.25, H2:H84) -> 3073000 | O14: =M2 - 3 * M20 -> -279.62408
H15: =E15 * D15 - C15 * D15 -> 0
A16: 3 | B16: 43920 | C16: 97 | D16: 1000 | E16: 90 | F16: =E16 - C16 -> -7 | G16: =(E16-C16)/(C16) -> -0.072164948 | H16: =E16 * D16 - C16 * D16 -> -7000 | I16: =MAX(E16:E21) -> 240 | J16: =(I16 *D16) - (C16 *D16) -> 143000 | K16: =IF(J16 > 0, "Profit This Week", "Negative This Week") -> Profit This Week | M16: Count_Of_Bells with 25% or higher profit (Highlighted in Red) | O16: Profit_Percentage
A17: 3 | B17: 43921 | C17: 97 | D17: 1000 | E17: 85 | F17: =E17 - C17 -> -12 | G17: =(E17-C17)/(C17) -> -0.12371134 | H17: =E17 * D17 - C17 * D17 -> -12000 | M17: =COUNTIF(G2:G84, ">= 0.25") -> 16 | O17: =COUNTIF(K2:K79,"Profit This Week")/12 -> 0.66666667
A18: 3 | B18: 43922 | C18: 97 | D18: 1000 | E18: 80 | F18: =E18 - C18 -> -17 | G18: =(E18-C18)/(C18) -> -0.17525773 | H18: =E18 * D18 - C18 * D18 -> -17000
A19: 3 | B19: 43923 | C19: 97 | D19: 1000 | E19: 120 | F19: =E19 - C19 -> 23 | G19: =(E19-C19)/(C19) -> 0.2371134 | H19: =E19 * D19 - C19 * D19 -> 23000 | M19: Standard_Deviation_Profit_Per_Turnip
A20: 3 | B20: 43924 | C20: 97 | D20: 1000 | E20: 240 | F20: =E20 - C20 -> 143 | G20: =(E20-C20)/(C20) -> 1.4742268 | H20: =E20 * D20 - C20 * D20 -> 143000 | M20: =STDEV(F2:F84) -> 105.30525
A21: 3 | B21: 43925 | C21: 97 | D21: 1000 | E21: 180 | F21: =E21 - C21 -> 83 | G21: =(E21-C21)/(C21) -> 0.8556701 | H21: =E21 * D21 - C21 * D21 -> 83000
H22: =E22 * D22 - C22 * D22 -> 0 | M22: Total_Profit (3 Months)
A23: 4 | B23: 43927 | C23: 90 | D23: 1000 | E23: 85 | F23: =E23 - C23 -> -5 | G23: =(E23-C23)/(C23) -> -0.055555556 | H23: =E23 * D23 - C23 * D23 -> -5000 | I23: =MAX(E23:E28) -> 550 | J23: =(I23 *D23) - (C23 *D23) -> 460000 | K23: =IF(J23 > 0, "Profit This Week", "Negative This Week") -> Profit This Week | M23: =SUM(J2:J79) -> 1733000
A24: 4 | B24: 43928 | C24: 90 | D24: 1000 | E24: 80 | F24: =E24 - C24 -> -10 | G24: =(E24-C24)/(C24) -> -0.11111111 | H24: =E24 * D24 - C24 * D24 -> -10000
A25: 4 | B25: 43929 | C25: 90 | D25: 1000 | E25: 75 | F25: =E25 - C25 -> -15 | G25: =(E25-C25)/(C25) -> -0.16666667 | H25: =E25 * D25 - C25 * D25 -> -15000
A26: 4 | B26: 43930 | C26: 90 | D26: 1000 | E26: 130 | F26: =E26 - C26 -> 40 | G26: =(E26-C26)/(C26) -> 0.44444444 | H26: =E26 * D26 - C26 * D26 -> 40000
A27: 4 | B27: 43931 | C27: 90 | D27: 1000 | E27: 300 | F27: =E27 - C27 -> 210 | G27: =(E27-C27)/(C27) -> 2.3333333 | H27: =E27 * D27 - C27 * D27 -> 210000 | M27: Explanation:
A28: 4 | B28: 43932 | C28: 90 | D28: 1000 | E28: 550 | F28: =E28 - C28 -> 460 | G28: =(E28-C28)/(C28) -> 5.1111111 | H28: =E28 * D28 - C28 * D28 -> 460000 | M28: We buy turnips once every Sunday in Animal Crossing.
H29: =E29 * D29 - C29 * D29 -> 0 | M29: From Monday to Saturday, the price changes every day.
A30: 5 | B30: 43934 | C30: 100 | D30: 1000 | E30: 95 | F30: =E30 - C30 -> -5 | G30: =(E30-C30)/(C30) -> -0.05 | H30: =E30 * D30 - C30 * D30 -> -5000 | I30: =MAX(E30:E35) -> 115 | J30: =(I30 *D30) - (C30 *D30) -> 15000 | K30: =IF(J30 > 0, "Profit This Week", "Negative This Week") -> Profit This Week | M30: This spreadsheet tracks the daily sell prices for 3 months in 2020 and calculates how much profit we would make if we sold on each day.
A31: 5 | B31: 43935 | C31: 100 | D31: 1000 | E31: 110 | F31: =E31 - C31 -> 10 | G31: =(E31-C31)/(C31) -> 0.1 | H31: =E31 * D31 - C31 * D31 -> 10000 | M31: For each week, we find the highest sell price and calculate the maximum possible profit from the 1,000 turnips we bought.
A32: 5 | B32: 43936 | C32: 100 | D32: 1000 | E32: 105 | F32: =E32 - C32 -> 5 | G32: =(E32-C32)/(C32) -> 0.05 | H32: =E32 * D32 - C32 * D32 -> 5000 | M32: So this sheet shows the best possible money we could have made each week and over the full 3-month period.
A33: 5 | B33: 43937 | C33: 100 | D33: 1000 | E33: 115 | F33: =E33 - C33 -> 15 | G33: =(E33-C33)/(C33) -> 0.15 | H33: =E33 * D33 - C33 * D33 -> 15000
A34: 5 | B34: 43938 | C34: 100 | D34: 1000 | E34: 108 | F34: =E34 - C34 -> 8 | G34: =(E34-C34)/(C34) -> 0.08 | H34: =E34 * D34 - C34 * D34 -> 8000 | M34: I write down the sell price every day that is offered
A35: 5 | B35: 43939 | C35: 100 | D35: 1000 | E35: 102 | F35: =E35 - C35 -> 2 | G35: =(E35-C35)/(C35) -> 0.02 | H35: =E35 * D35 - C35 * D35 -> 2000
H36: =E36 * D36 - C36 * D36 -> 0
A37: 6 | B37: 43941 | C37: 93 | D37: 1000 | E37: 88 | F37: =E37 - C37 -> -5 | G37: =(E37-C37)/(C37) -> -0.053763441 | H37: =E37 * D37 - C37 * D37 -> -5000 | I37: =MAX(E37:E42) -> 88 | J37: =(I37 *D37) - (C37 *D37) -> -5000 | K37: =IF(J37 > 0, "Profit This Week", "Negative This Week") -> Negative This Week
A38: 6 | B38: 43942 | C38: 93 | D38: 1000 | E38: 84 | F38: =E38 - C38 -> -9 | G38: =(E38-C38)/(C38) -> -0.096774194 | H38: =E38 * D38 - C38 * D38 -> -9000
A39: 6 | B39: 43943 | C39: 93 | D39: 1000 | E39: 80 | F39: =E39 - C39 -> -13 | G39: =(E39-C39)/(C39) -> -0.13978495 | H39: =E39 * D39 - C39 * D39 -> -13000
A40: 6 | B40: 43944 | C40: 93 | D40: 1000 | E40: 75 | F40: =E40 - C40 -> -18 | G40: =(E40-C40)/(C40) -> -0.19354839 | H40: =E40 * D40 - C40 * D40 -> -18000
...

Sheet Deep_Sea_Creature
A1: Week | B1: Date | C1: Common_Count | D1: Medium_Count | E1: Large_Count | F1: Ultra_Count | G1: Common_Avg | H1: Medium_Avg | I1: Large_Avg | J1: Ultra_Avg | K1: Total_Day_Value | L1: Subtotal_For_Week | M1: Fish_Name | N1: Sell_Price | O1: Rarity_Class | P1: Combined | Q1: Get_Sell_Price_Using_Left | R1: Get_Sell_Price_Using_Mid | S1: Get_Rarity_Class - RIGHT(RIGHT()) | T1: Get_Rarity_Class - FIND(FIND()) | U1: Get_Rarity_Class - MID() | V1: Owen_Tran_8103
A2: 1 | B2: 43906 | C2: 16 | D2: 4 | E2: 1 | F2: 0 | G2: 400 | H2: 1200 | I2: 4000 | J2: 12000 | K2: =C2 * G2 + D2 * H2 + E2 * I2 + F2 * J2 -> 15200 | L2: =SUM(K2:K7) -> 96400 | M2: Bitterling | N2: 900 | O2: Low | P2: =M2 & "_" & N2 & "_" & O2 -> Bitterling_900_Low | Q2: =LEFT(RIGHT(P2,LEN(P2)-FIND("_",P2)),FIND("_",RIGHT(P2,LEN(P2)-FIND("_",P2)))-1) -> 900 | R2: =MID(P2, FIND("_", P2)+1, FIND("_", P2, FIND("_", P2)+1) - FIND("_", P2)-1) -> 900 | S2: =RIGHT(RIGHT(P2,LEN(P2)-FIND("_",P2)),LEN(RIGHT(P2,LEN(P2)-FIND("_",P2)))-FIND("_",RIGHT(P2,LEN(P2)-FIND("_",P2)))) -> Low | T2: =RIGHT(P2,LEN(P2)-FIND("_",P2,FIND("_",P2)+1)) -> Low | U2: =MID(P2,FIND("_",P2,FIND("_",P2)+1)+1,LEN(P2)-FIND("_",P2,FIND("_",P2)+1)) -> Low
A3: 1 | B3: 43907 | C3: 15 | D3: 5 | E3: 1 | F3: 0 | G3: 400 | H3: 1200 | I3: 4000 | J3: 12000 | K3: =C3 * G3 + D3 * H3 + E3 * I3 + F3 * J3 -> 16000 | M3: Pale chub | N3: 200 | O3: Low | P3: =M3 & "_" & N3 & "_" & O3 -> Pale chub_200_Low | Q3: =LEFT(RIGHT(P3,LEN(P3)-FIND("_",P3)),FIND("_",RIGHT(P3,LEN(P3)-FIND("_",P3)))-1) -> 200 | R3: =MID(P3, FIND("_", P3)+1, FIND("_", P3, FIND("_", P3)+1) - FIND("_", P3)-1) -> 200 | S3: =RIGHT(RIGHT(P3,LEN(P3)-FIND("_",P3)),LEN(RIGHT(P3,LEN(P3)-FIND("_",P3)))-FIND("_",RIGHT(P3,LEN(P3)-FIND("_",P3)))) -> Low | T3: =RIGHT(P3,LEN(P3)-FIND("_",P3,FIND("_",P3)+1)) -> Low | U3: =MID(P3,FIND("_",P3,FIND("_",P3)+1)+1,LEN(P3)-FIND("_",P3,FIND("_",P3)+1)) -> Low | V3: Simple_Left
A4: 1 | B4: 43908 | C4: 17 | D4: 3 | E4: 1 | F4: 0 | G4: 400 | H4: 1200 | I4: 4000 | J4: 12000 | K4: =C4 * G4 + D4 * H4 + E4 * I4 + F4 * J4 -> 14400 | M4: Crucian carp | N4: 160 | O4: Low | P4: =M4 & "_" & N4 & "_" & O4 -> Crucian carp_160_Low | Q4: =LEFT(RIGHT(P4,LEN(P4)-FIND("_",P4)),FIND("_",RIGHT(P4,LEN(P4)-FIND("_",P4)))-1) -> 160 | R4: =MID(P4, FIND("_", P4)+1, FIND("_", P4, FIND("_", P4)+1) - FIND("_", P4)-1) -> 160 | S4: =RIGHT(RIGHT(P4,LEN(P4)-FIND("_",P4)),LEN(RIGHT(P4,LEN(P4)-FIND("_",P4)))-FIND("_",RIGHT(P4,LEN(P4)-FIND("_",P4)))) -> Low | T4: =RIGHT(P4,LEN(P4)-FIND("_",P4,FIND("_",P4)+1)) -> Low | U4: =MID(P4,FIND("_",P4,FIND("_",P4)+1)+1,LEN(P4)-FIND("_",P4,FIND("_",P4)+1)) -> Low | V4: =LEFT(V1, FIND("_", V1)-1) -> Owen
A5: 1 | B5: 43909 | C5: 14 | D5: 6 | E5: 1 | F5: 0 | G5: 400 | H5: 1200 | I5: 4000 | J5: 12000 | K5: =C5 * G5 + D5 * H5 + E5 * I5 + F5 * J5 -> 16800 | M5: Dace | N5: 240 | O5: Low | P5: =M5 & "_" & N5 & "_" & O5 -> Dace_240_Low | Q5: =LEFT(RIGHT(P5,LEN(P5)-FIND("_",P5)),FIND("_",RIGHT(P5,LEN(P5)-FIND("_",P5)))-1) -> 240 | R5: =MID(P5, FIND("_", P5)+1, FIND("_", P5, FIND("_", P5)+1) - FIND("_", P5)-1) -> 240 | S5: =RIGHT(RIGHT(P5,LEN(P5)-FIND("_",P5)),LEN(RIGHT(P5,LEN(P5)-FIND("_",P5)))-FIND("_",RIGHT(P5,LEN(P5)-FIND("_",P5)))) -> Low | T5: =RIGHT(P5,LEN(P5)-FIND("_",P5,FIND("_",P5)+1)) -> Low | U5: =MID(P5,FIND("_",P5,FIND("_",P5)+1)+1,LEN(P5)-FIND("_",P5,FIND("_",P5)+1)) -> Low
A6: 1 | B6: 43910 | C6: 16 | D6: 4 | E6: 2 | F6: 0 | G6: 400 | H6: 1200 | I6: 4000 | J6: 12000 | K6: =C6 * G6 + D6 * H6 + E6 * I6 + F6 * J6 -> 19200 | M6: Carp | N6: 300 | O6: Low | P6: =M6 & "_" & N6 & "_" & O6 -> Carp_300_Low | Q6: =LEFT(RIGHT(P6,LEN(P6)-FIND("_",P6)),FIND("_",RIGHT(P6,LEN(P6)-FIND("_",P6)))-1) -> 300 | R6: =MID(P6, FIND("_", P6)+1, FIND("_", P6, FIND("_", P6)+1) - FIND("_", P6)-1) -> 300 | S6: =RIGHT(RIGHT(P6,LEN(P6)-FIND("_",P6)),LEN(RIGHT(P6,LEN(P6)-FIND("_",P6)))-FIND("_",RIGHT(P6,LEN(P6)-FIND("_",P6)))) -> Low | T6: =RIGHT(P6,LEN(P6)-FIND("_",P6,FIND("_",P6)+1)) -> Low | U6: =MID(P6,FIND("_",P6,FIND("_",P6)+1)+1,LEN(P6)-FIND("_",P6,FIND("_",P6)+1)) -> Low | V6: Simple_Right
A7: 1 | B7: 43911 | C7: 15 | D7: 4 | E7: 1 | F7: 0 | G7: 400 | H7: 1200 | I7: 4000 | J7: 12000 | K7: =C7 * G7 + D7 * H7 + E7 * I7 + F7 * J7 -> 14800 | M7: Koi | N7: 4000 | O7: High | P7: =M7 & "_" & N7 & "_" & O7 -> Koi_4000_High | Q7: =LEFT(RIGHT(P7,LEN(P7)-FIND("_",P7)),FIND("_",RIGHT(P7,LEN(P7)-FIND("_",P7)))-1) -> 4000 | R7: =MID(P7, FIND("_", P7)+1, FIND("_", P7, FIND("_", P7)+1) - FIND("_", P7)-1) -> 4000 | S7: =RIGHT(RIGHT(P7,LEN(P7)-FIND("_",P7)),LEN(RIGHT(P7,LEN(P7)-FIND("_",P7)))-FIND("_",RIGHT(P7,LEN(P7)-FIND("_",P7)))) -> High | T7: =RIGHT(P7,LEN(P7)-FIND("_",P7,FIND("_",P7)+1)) -> High | U7: =MID(P7,FIND("_",P7,FIND("_",P7)+1)+1,LEN(P7)-FIND("_",P7,FIND("_",P7)+1)) -> High | V7: =RIGHT(V1, LEN(V1) - FIND("_",V1)) -> Tran_8103
M8: Goldfish | N8: 1300 | O8: Medium | P8: =M8 & "_" & N8 & "_" & O8 -> Goldfish_1300_Medium | Q8: =LEFT(RIGHT(P8,LEN(P8)-FIND("_",P8)),FIND("_",RIGHT(P8,LEN(P8)-FIND("_",P8)))-1) -> 1300 | R8: =MID(P8, FIND("_", P8)+1, FIND("_", P8, FIND("_", P8)+1) - FIND("_", P8)-1) -> 1300 | S8: =RIGHT(RIGHT(P8,LEN(P8)-FIND("_",P8)),LEN(RIGHT(P8,LEN(P8)-FIND("_",P8)))-FIND("_",RIGHT(P8,LEN(P8)-FIND("_",P8)))) -> Medium | T8: =RIGHT(P8,LEN(P8)-FIND("_",P8,FIND("_",P8)+1)) -> Medium | U8: =MID(P8,FIND("_",P8,FIND("_",P8)+1)+1,LEN(P8)-FIND("_",P8,FIND("_",P8)+1)) -> Medium | V8: =RIGHT(V7, LEN(V7) - FIND("_", V7)) -> 8103
A9: 2 | B9: 43913 | C9: 16 | D9: 4 | E9: 1 | F9: 0 | G9: 400 | H9: 1200 | I9: 4000 | J9: 12000 | K9: =C9 * G9 + D9 * H9 + E9 * I9 + F9 * J9 -> 15200 | L9: =SUM(K9:K14) -> 104400 | M9: Pop-eyed goldfish | N9: 1300 | O9: Medium | P9: =M9 & "_" & N9 & "_" & O9 -> Pop-eyed goldfish_1300_Medium | Q9: =LEFT(RIGHT(P9,LEN(P9)-FIND("_",P9)),FIND("_",RIGHT(P9,LEN(P9)-FIND("_",P9)))-1) -> 1300 | R9: =MID(P9, FIND("_", P9)+1, FIND("_", P9, FIND("_", P9)+1) - FIND("_", P9)-1) -> 1300 | S9: =RIGHT(RIGHT(P9,LEN(P9)-FIND("_",P9)),LEN(RIGHT(P9,LEN(P9)-FIND("_",P9)))-FIND("_",RIGHT(P9,LEN(P9)-FIND("_",P9)))) -> Medium | T9: =RIGHT(P9,LEN(P9)-FIND("_",P9,FIND("_",P9)+1)) -> Medium | U9: =MID(P9,FIND("_",P9,FIND("_",P9)+1)+1,LEN(P9)-FIND("_",P9,FIND("_",P9)+1)) -> Medium | V9: =RIGHT(RIGHT(V1, LEN(V1) - FIND("_", V1)), LEN(RIGHT(V1, LEN(V1) - FIND("_", V1))) - FIND("_",RIGHT(V1, LEN(V1) - FIND("_", V1)))) -> 8103
A10: 2 | B10: 43914 | C10: 15 | D10: 5 | E10: 1 | F10: 0 | G10: 400 | H10: 1200 | I10: 4000 | J10: 12000 | K10: =C10 * G10 + D10 * H10 + E10 * I10 + F10 * J10 -> 16000 | M10: Ranchu goldfish | N10: 4500 | O10: High | P10: =M10 & "_" & N10 & "_" & O10 -> Ranchu goldfish_4500_High | Q10: =LEFT(RIGHT(P10,LEN(P10)-FIND("_",P10)),FIND("_",RIGHT(P10,LEN(P10)-FIND("_",P10)))-1) -> 4500 | R10: =MID(P10, FIND("_", P10)+1, FIND("_", P10, FIND("_", P10)+1) - FIND("_", P10)-1) -> 4500 | S10: =RIGHT(RIGHT(P10,LEN(P10)-FIND("_",P10)),LEN(RIGHT(P10,LEN(P10)-FIND("_",P10)))-FIND("_",RIGHT(P10,LEN(P10)-FIND("_",P10)))) -> High | T10: =RIGHT(P10,LEN(P10)-FIND("_",P10,FIND("_",P10)+1)) -> High | U10: =MID(P10,FIND("_",P10,FIND("_",P10)+1)+1,LEN(P10)-FIND("_",P10,FIND("_",P10)+1)) -> High
A11: 2 | B11: 43915 | C11: 17 | D11: 3 | E11: 1 | F11: 0 | G11: 400 | H11: 1200 | I11: 4000 | J11: 12000 | K11: =C11 * G11 + D11 * H11 + E11 * I11 + F11 * J11 -> 14400 | M11: Killifish | N11: 300 | O11: Low | P11: =M11 & "_" & N11 & "_" & O11 -> Killifish_300_Low | Q11: =LEFT(RIGHT(P11,LEN(P11)-FIND("_",P11)),FIND("_",RIGHT(P11,LEN(P11)-FIND("_",P11)))-1) -> 300 | R11: =MID(P11, FIND("_", P11)+1, FIND("_", P11, FIND("_", P11)+1) - FIND("_", P11)-1) -> 300 | S11: =RIGHT(RIGHT(P11,LEN(P11)-FIND("_",P11)),LEN(RIGHT(P11,LEN(P11)-FIND("_",P11)))-FIND("_",RIGHT(P11,LEN(P11)-FIND("_",P11)))) -> Low | T11: =RIGHT(P11,LEN(P11)-FIND("_",P11,FIND("_",P11)+1)) -> Low | U11: =MID(P11,FIND("_",P11,FIND("_",P11)+1)+1,LEN(P11)-FIND("_",P11,FIND("_",P11)+1)) -> Low | V11: Simple_Mid
A12: 2 | B12: 43916 | C12: 16 | D12: 4 | E12: 1 | F12: 0 | G12: 400 | H12: 1200 | I12: 4000 | J12: 12000 | K12: =C12 * G12 + D12 * H12 + E12 * I12 + F12 * J12 -> 15200 | M12: Crawfish | N12: 200 | O12: Low | P12: =M12 & "_" & N12 & "_" & O12 -> Crawfish_200_Low | Q12: =LEFT(RIGHT(P12,LEN(P12)-FIND("_",P12)),FIND("_",RIGHT(P12,LEN(P12)-FIND("_",P12)))-1) -> 200 | R12: =MID(P12, FIND("_", P12)+1, FIND("_", P12, FIND("_", P12)+1) - FIND("_", P12)-1) -> 200 | S12: =RIGHT(RIGHT(P12,LEN(P12)-FIND("_",P12)),LEN(RIGHT(P12,LEN(P12)-FIND("_",P12)))-FIND("_",RIGHT(P12,LEN(P12)-FIND("_",P12)))) -> Low | T12: =RIGHT(P12,LEN(P12)-FIND("_",P12,FIND("_",P12)+1)) -> Low | U12: =MID(P12,FIND("_",P12,FIND("_",P12)+1)+1,LEN(P12)-FIND("_",P12,FIND("_",P12)+1)) -> Low | V12: =MID(V1, 6, 4) -> Tran
A13: 2 | B13: 43917 | C13: 14 | D13: 6 | E13: 1 | F13: 0 | G13: 400 | H13: 1200 | I13: 4000 | J13: 12000 | K13: =C13 * G13 + D13 * H13 + E13 * I13 + F13 * J13 -> 16800 | M13: Soft-shelled turtle | N13: 3750 | O13: Medium | P13: =M13 & "_" & N13 & "_" & O13 -> Soft-shelled turtle_3750_Medium | Q13: =LEFT(RIGHT(P13,LEN(P13)-FIND("_",P13)),FIND("_",RIGHT(P13,LEN(P13)-FIND("_",P13)))-1) -> 3750 | R13: =MID(P13, FIND("_", P13)+1, FIND("_", P13, FIND("_", P13)+1) - FIND("_", P13)-1) -> 3750 | S13: =RIGHT(RIGHT(P13,LEN(P13)-FIND("_",P13)),LEN(RIGHT(P13,LEN(P13)-FIND("_",P13)))-FIND("_",RIGHT(P13,LEN(P13)-FIND("_",P13)))) -> Medium | T13: =RIGHT(P13,LEN(P13)-FIND("_",P13,FIND("_",P13)+1)) -> Medium | U13: =MID(P13,FIND("_",P13,FIND("_",P13)+1)+1,LEN(P13)-FIND("_",P13,FIND("_",P13)+1)) -> Medium
A14: 2 | B14: 43918 | C14: 15 | D14: 4 | E14: 1 | F14: 1 | G14: 400 | H14: 1200 | I14: 4000 | J14: 12000 | K14: =C14 * G14 + D14 * H14 + E14 * I14 + F14 * J14 -> 26800 | M14: Snapping turtle | N14: 5000 | O14: High | P14: =M14 & "_" & N14 & "_" & O14 -> Snapping turtle_5000_High | Q14: =LEFT(RIGHT(P14,LEN(P14)-FIND("_",P14)),FIND("_",RIGHT(P14,LEN(P14)-FIND("_",P14)))-1) -> 5000 | R14: =MID(P14, FIND("_", P14)+1, FIND("_", P14, FIND("_", P14)+1) - FIND("_", P14)-1) -> 5000 | S14: =RIGHT(RIGHT(P14,LEN(P14)-FIND("_",P14)),LEN(RIGHT(P14,LEN(P14)-FIND("_",P14)))-FIND("_",RIGHT(P14,LEN(P14)-FIND("_",P14)))) -> High | T14: =RIGHT(P14,LEN(P14)-FIND("_",P14,FIND("_",P14)+1)) -> High | U14: =MID(P14,FIND("_",P14,FIND("_",P14)+1)+1,LEN(P14)-FIND("_",P14,FIND("_",P14)+1)) -> High
M15: Tadpole | N15: 100 | O15: Low | P15: =M15 & "_" & N15 & "_" & O15 -> Tadpole_100_Low | Q15: =LEFT(RIGHT(P15,LEN(P15)-FIND("_",P15)),FIND("_",RIGHT(P15,LEN(P15)-FIND("_",P15)))-1) -> 100 | R15: =MID(P15, FIND("_", P15)+1, FIND("_", P15, FIND("_", P15)+1) - FIND("_", P15)-1) -> 100 | S15: =RIGHT(RIGHT(P15,LEN(P15)-FIND("_",P15)),LEN(RIGHT(P15,LEN(P15)-FIND("_",P15)))-FIND("_",RIGHT(P15,LEN(P15)-FIND("_",P15)))) -> Low | T15: =RIGHT(P15,LEN(P15)-FIND("_",P15,FIND("_",P15)+1)) -> Low | U15: =MID(P15,FIND("_",P15,FIND("_",P15)+1)+1,LEN(P15)-FIND("_",P15,FIND("_",P15)+1)) -> Low
A16: 3 | B16: 43920 | C16: 16 | D16: 4 | E16: 1 | F16: 0 | G16: 400 | H16: 1200 | I16: 4000 | J16: 12000 | K16: =C16 * G16 + D16 * H16 + E16 * I16 + F16 * J16 -> 15200 | L16: =SUM(K16:K21) -> 96400 | M16: Frog | N16: 120 | O16: Low | P16: =M16 & "_" & N16 & "_" & O16 -> Frog_120_Low | Q16: =LEFT(RIGHT(P16,LEN(P16)-FIND("_",P16)),FIND("_",RIGHT(P16,LEN(P16)-FIND("_",P16)))-1) -> 120 | R16: =MID(P16, FIND("_", P16)+1, FIND("_", P16, FIND("_", P16)+1) - FIND("_", P16)-1) -> 120 | S16: =RIGHT(RIGHT(P16,LEN(P16)-FIND("_",P16)),LEN(RIGHT(P16,LEN(P16)-FIND("_",P16)))-FIND("_",RIGHT(P16,LEN(P16)-FIND("_",P16)))) -> Low | T16: =RIGHT(P16,LEN(P16)-FIND("_",P16,FIND("_",P16)+1)) -> Low | U16: =MID(P16,FIND("_",P16,FIND("_",P16)+1)+1,LEN(P16)-FIND("_",P16,FIND("_",P16)+1)) -> Low
A17: 3 | B17: 43921 | C17: 15 | D17: 5 | E17: 1 | F17: 0 | G17: 400 | H17: 1200 | I17: 4000 | J17: 12000 | K17: =C17 * G17 + D17 * H17 + E17 * I17 + F17 * J17 -> 16000 | M17: Freshwater goby | N17: 400 | O17: Low | P17: =M17 & "_" & N17 & "_" & O17 -> Freshwater goby_400_Low | Q17: =LEFT(RIGHT(P17,LEN(P17)-FIND("_",P17)),FIND("_",RIGHT(P17,LEN(P17)-FIND("_",P17)))-1) -> 400 | R17: =MID(P17, FIND("_", P17)+1, FIND("_", P17, FIND("_", P17)+1) - FIND("_", P17)-1) -> 400 | S17: =RIGHT(RIGHT(P17,LEN(P17)-FIND("_",P17)),LEN(RIGHT(P17,LEN(P17)-FIND("_",P17)))-FIND("_",RIGHT(P17,LEN(P17)-FIND("_",P17)))) -> Low | T17: =RIGHT(P17,LEN(P17)-FIND("_",P17,FIND("_",P17)+1)) -> Low | U17: =MID(P17,FIND("_",P17,FIND("_",P17)+1)+1,LEN(P17)-FIND("_",P17,FIND("_",P17)+1)) -> Low
A18: 3 | B18: 43922 | C18: 17 | D18: 3 | E18: 1 | F18: 0 | G18: 400 | H18: 1200 | I18: 4000 | J18: 12000 | K18: =C18 * G18 + D18 * H18 + E18 * I18 + F18 * J18 -> 14400 | M18: Loach | N18: 400 | O18: Low | P18: =M18 & "_" & N18 & "_" & O18 -> Loach_400_Low | Q18: =LEFT(RIGHT(P18,LEN(P18)-FIND("_",P18)),FIND("_",RIGHT(P18,LEN(P18)-FIND("_",P18)))-1) -> 400 | R18: =MID(P18, FIND("_", P18)+1, FIND("_", P18, FIND("_", P18)+1) - FIND("_", P18)-1) -> 400 | S18: =RIGHT(RIGHT(P18,LEN(P18)-FIND("_",P18)),LEN(RIGHT(P18,LEN(P18)-FIND("_",P18)))-FIND("_",RIGHT(P18,LEN(P18)-FIND("_",P18)))) -> Low | T18: =RIGHT(P18,LEN(P18)-FIND("_",P18,FIND("_",P18)+1)) -> Low | U18: =MID(P18,FIND("_",P18,FIND("_",P18)+1)+1,LEN(P18)-FIND("_",P18,FIND("_",P18)+1)) -> Low
A19: 3 | B19: 43923 | C19: 14 | D19: 6 | E19: 1 | F19: 0 | G19: 400 | H19: 1200 | I19: 4000 | J19: 12000 | K19: =C19 * G19 + D19 * H19 + E19 * I19 + F19 * J19 -> 16800 | M19: Catfish | N19: 800 | O19: Low | P19: =M19 & "_" & N19 & "_" & O19 -> Catfish_800_Low | Q19: =LEFT(RIGHT(P19,LEN(P19)-FIND("_",P19)),FIND("_",RIGHT(P19,LEN(P19)-FIND("_",P19)))-1) -> 800 | R19: =MID(P19, FIND("_", P19)+1, FIND("_", P19, FIND("_", P19)+1) - FIND("_", P19)-1) -> 800 | S19: =RIGHT(RIGHT(P19,LEN(P19)-FIND("_",P19)),LEN(RIGHT(P19,LEN(P19)-FIND("_",P19)))-FIND("_",RIGHT(P19,LEN(P19)-FIND("_",P19)))) -> Low | T19: =RIGHT(P19,LEN(P19)-FIND("_",P19,FIND("_",P19)+1)) -> Low | U19: =MID(P19,FIND("_",P19,FIND("_",P19)+1)+1,LEN(P19)-FIND("_",P19,FIND("_",P19)+1)) -> Low
A20: 3 | B20: 43924 | C20: 16 | D20: 4 | E20: 2 | F20: 0 | G20: 400 | H20: 1200 | I20: 4000 | J20: 12000 | K20: =C20 * G20 + D20 * H20 + E20 * I20 + F20 * J20 -> 19200 | M20: Giant snakehead | N20: 5500 | O20: High | P20: =M20 & "_" & N20 & "_" & O20 -> Giant snakehead_5500_High | Q20: =LEFT(RIGHT(P20,LEN(P20)-FIND("_",P20)),FIND("_",RIGHT(P20,LEN(P20)-FIND("_",P20)))-1) -> 5500 | R20: =MID(P20, FIND("_", P20)+1, FIND("_", P20, FIND("_", P20)+1) - FIND("_", P20)-1) -> 5500 | S20: =RIGHT(RIGHT(P20,LEN(P20)-FIND("_",P20)),LEN(RIGHT(P20,LEN(P20)-FIND("_",P20)))-FIND("_",RIGHT(P20,LEN(P20)-FIND("_",P20)))) -> High | T20: =RIGHT(P20,LEN(P20)-FIND("_",P20,FIND("_",P20)+1)) -> High | U20: =MID(P20,FIND("_",P20,FIND("_",P20)+1)+1,LEN(P20)-FIND("_",P20,FIND("_",P20)+1)) -> High
A21: 3 | B21: 43925 | C21: 15 | D21: 4 | E21: 1 | F21: 0 | G21: 400 | H21: 1200 | I21: 4000 | J21: 12000 | K21: =C21 * G21 + D21 * H21 + E21 * I21 + F21 * J21 -> 14800 | M21: Bluegill | N21: 180 | O21: Low | P21: =M21 & "_" & N21 & "_" & O21 -> Bluegill_180_Low | Q21: =LEFT(RIGHT(P21,LEN(P21)-FIND("_",P21)),FIND("_",RIGHT(P21,LEN(P21)-FIND("_",P21)))-1) -> 180 | R21: =MID(P21, FIND("_", P21)+1, FIND("_", P21, FIND("_", P21)+1) - FIND("_", P21)-1) -> 180 | S21: =RIGHT(RIGHT(P21,LEN(P21)-FIND("_",P21)),LEN(RIGHT(P21,LEN(P21)-FIND("_",P21)))-FIND("_",RIGHT(P21,LEN(P21)-FIND("_",P21)))) -> Low | T21: =RIGHT(P21,LEN(P21)-FIND("_",P21,FIND("_",P21)+1)) -> Low | U21: =MID(P21,FIND("_",P21,FIND("_",P21)+1)+1,LEN(P21)-FIND("_",P21,FIND("_",P21)+1)) -> Low
M22: Yellow perch | N22: 300 | O22: Low | P22: =M22 & "_" & N22 & "_" & O22 -> Yellow perch_300_Low | Q22: =LEFT(RIGHT(P22,LEN(P22)-FIND("_",P22)),FIND("_",RIGHT(P22,LEN(P22)-FIND("_",P22)))-1) -> 300 | R22: =MID(P22, FIND("_", P22)+1, FIND("_", P22, FIND("_", P22)+1) - FIND("_", P22)-1) -> 300 | S22: =RIGHT(RIGHT(P22,LEN(P22)-FIND("_",P22)),LEN(RIGHT(P22,LEN(P22)-FIND("_",P22)))-FIND("_",RIGHT(P22,LEN(P22)-FIND("_",P22)))) -> Low | T22: =RIGHT(P22,LEN(P22)-FIND("_",P22,FIND("_",P22)+1)) -> Low | U22: =MID(P22,FIND("_",P22,FIND("_",P22)+1)+1,LEN(P22)-FIND("_",P22,FIND("_",P22)+1)) -> Low
A23: 4 | B23: 43927 | C23: 17 | D23: 3 | E23: 1 | F23: 0 | G23: 400 | H23: 1200 | I23: 4000 | J23: 12000 | K23: =C23 * G23 + D23 * H23 + E23 * I23 + F23 * J23 -> 14400 | L23: =SUM(K23:K28) -> 96400 | M23: Black bass | N23: 400 | O23: Low | P23: =M23 & "_" & N23 & "_" & O23 -> Black bass_400_Low | Q23: =LEFT(RIGHT(P23,LEN(P23)-FIND("_",P23)),FIND("_",RIGHT(P23,LEN(P23)-FIND("_",P23)))-1) -> 400 | R23: =MID(P23, FIND("_", P23)+1, FIND("_", P23, FIND("_", P23)+1) - FIND("_", P23)-1) -> 400 | S23: =RIGHT(RIGHT(P23,LEN(P23)-FIND("_",P23)),LEN(RIGHT(P23,LEN(P23)-FIND("_",P23)))-FIND("_",RIGHT(P23,LEN(P23)-FIND("_",P23)))) -> Low | T23: =RIGHT(P23,LEN(P23)-FIND("_",P23,FIND("_",P23)+1)) -> Low | U23: =MID(P23,FIND("_",P23,FIND("_",P23)+1)+1,LEN(P23)-FIND("_",P23,FIND("_",P23)+1)) -> Low
A24: 4 | B24: 43928 | C24: 16 | D24: 4 | E24: 1 | F24: 0 | G24: 400 | H24: 1200 | I24: 4000 | J24: 12000 | K24: =C24 * G24 + D24 * H24 + E24 * I24 + F24 * J24 -> 15200 | M24: Tilapia | N24: 800 | O24: Low | P24: =M24 & "_" & N24 & "_" & O24 -> Tilapia_800_Low | Q24: =LEFT(RIGHT(P24,LEN(P24)-FIND("_",P24)),FIND("_",RIGHT(P24,LEN(P24)-FIND("_",P24)))-1) -> 800 | R24: =MID(P24, FIND("_", P24)+1, FIND("_", P24, FIND("_", P24)+1) - FIND("_", P24)-1) -> 800 | S24: =RIGHT(RIGHT(P24,LEN(P24)-FIND("_",P24)),LEN(RIGHT(P24,LEN(P24)-FIND("_",P24)))-FIND("_",RIGHT(P24,LEN(P24)-FIND("_",P24)))) -> Low | T24: =RIGHT(P24,LEN(P24)-FIND("_",P24,FIND("_",P24)+1)) -> Low | U24: =MID(P24,FIND("_",P24,FIND("_",P24)+1)+1,LEN(P24)-FIND("_",P24,FIND("_",P24)+1)) -> Low
A25: 4 | B25: 43929 | C25: 15 | D25: 5 | E25: 1 | F25: 0 | G25: 400 | H25: 1200 | I25: 4000 | J25: 12000 | K25: =C25 * G25 + D25 * H25 + E25 * I25 + F25 * J25 -> 16000 | M25: Pike | N25: 1800 | O25: Medium | P25: =M25 & "_" & N25 & "_" & O25 -> Pike_1800_Medium | Q25: =LEFT(RIGHT(P25,LEN(P25)-FIND("_",P25)),FIND("_",RIGHT(P25,LEN(P25)-FIND("_",P25)))-1) -> 1800 | R25: =MID(P25, FIND("_", P25)+1, FIND("_", P25, FIND("_", P25)+1) - FIND("_", P25)-1) -> 1800 | S25: =RIGHT(RIGHT(P25,LEN(P25)-FIND("_",P25)),LEN(RIGHT(P25,LEN(P25)-FIND("_",P25)))-FIND("_",RIGHT(P25,LEN(P25)-FIND("_",P25)))) -> Medium | T25: =RIGHT(P25,LEN(P25)-FIND("_",P25,FIND("_",P25)+1)) -> Medium | U25: =MID(P25,FIND("_",P25,FIND("_",P25)+1)+1,LEN(P25)-FIND("_",P25,FIND("_",P25)+1)) -> Medium
A26: 4 | B26: 43930 | C26: 14 | D26: 6 | E26: 1 | F26: 0 | G26: 400 | H26: 1200 | I26: 4000 | J26: 12000 | K26: =C26 * G26 + D26 * H26 + E26 * I26 + F26 * J26 -> 16800 | M26: Pond smelt | N26: 400 | O26: Low | P26: =M26 & "_" & N26 & "_" & O26 -> Pond smelt_400_Low | Q26: =LEFT(RIGHT(P26,LEN(P26)-FIND("_",P26)),FIND("_",RIGHT(P26,LEN(P26)-FIND("_",P26)))-1) -> 400 | R26: =MID(P26, FIND("_", P26)+1, FIND("_", P26, FIND("_", P26)+1) - FIND("_", P26)-1) -> 400 | S26: =RIGHT(RIGHT(P26,LEN(P26)-FIND("_",P26)),LEN(RIGHT(P26,LEN(P26)-FIND("_",P26)))-FIND("_",RIGHT(P26,LEN(P26)-FIND("_",P26)))) -> Low | T26: =RIGHT(P26,LEN(P26)-FIND("_",P26,FIND("_",P26)+1)) -> Low | U26: =MID(P26,FIND("_",P26,FIND("_",P26)+1)+1,LEN(P26)-FIND("_",P26,FIND("_",P26)+1)) -> Low
A27: 4 | B27: 43931 | C27: 16 | D27: 4 | E27: 2 | F27: 0 | G27: 400 | H27: 1200 | I27: 4000 | J27: 12000 | K27: =C27 * G27 + D27 * H27 + E27 * I27 + F27 * J27 -> 19200 | M27: Sweetfish | N27: 900 | O27: Low | P27: =M27 & "_" & N27 & "_" & O27 -> Sweetfish_900_Low | Q27: =LEFT(RIGHT(P27,LEN(P27)-FIND("_",P27)),FIND("_",RIGHT(P27,LEN(P27)-FIND("_",P27)))-1) -> 900 | R27: =MID(P27, FIND("_", P27)+1, FIND("_", P27, FIND("_", P27)+1) - FIND("_", P27)-1) -> 900 | S27: =RIGHT(RIGHT(P27,LEN(P27)-FIND("_",P27)),LEN(RIGHT(P27,LEN(P27)-FIND("_",P27)))-FIND("_",RIGHT(P27,LEN(P27)-FIND("_",P27)))) -> Low | T27: =RIGHT(P27,LEN(P27)-FIND("_",P27,FIND("_",P27)+1)) -> Low | U27: =MID(P27,FIND("_",P27,FIND("_",P27)+1)+1,LEN(P27)-FIND("_",P27,FIND("_",P27)+1)) -> Low
A28: 4 | B28: 43932 | C28: 15 | D28: 4 | E28: 1 | F28: 0 | G28: 400 | H28: 1200 | I28: 4000 | J28: 12000 | K28: =C28 * G28 + D28 * H28 + E28 * I28 + F28 * J28 -> 14800 | M28: Cherry salmon | N28: 1000 | O28: Medium | P28: =M28 & "_" & N28 & "_" & O28 -> Cherry salmon_1000_Medium | Q28: =LEFT(RIGHT(P28,LEN(P28)-FIND("_",P28)),FIND("_",RIGHT(P28,LEN(P28)-FIND("_",P28)))-1) -> 1000 | R28: =MID(P28, FIND("_", P28)+1, FIND("_", P28, FIND("_", P28)+1) - FIND("_", P28)-1) -> 1000 | S28: =RIGHT(RIGHT(P28,LEN(P28)-FIND("_",P28)),LEN(RIGHT(P28,LEN(P28)-FIND("_",P28)))-FIND("_",RIGHT(P28,LEN(P28)-FIND("_",P28)))) -> Medium | T28: =RIGHT(P28,LEN(P28)-FIND("_",P28,FIND("_",P28)+1)) -> Medium | U28: =MID(P28,FIND("_",P28,FIND("_",P28)+1)+1,LEN(P28)-FIND("_",P28,FIND("_",P28)+1)) -> Medium
M29: Char | N29: 3800 | O29: Medium | P29: =M29 & "_" & N29 & "_" & O29 -> Char_3800_Medium | Q29: =LEFT(RIGHT(P29,LEN(P29)-FIND("_",P29)),FIND("_",RIGHT(P29,LEN(P29)-FIND("_",P29)))-1) -> 3800 | R29: =MID(P29, FIND("_", P29)+1, FIND("_", P29, FIND("_", P29)+1) - FIND("_", P29)-1) -> 3800 | S29: =RIGHT(RIGHT(P29,LEN(P29)-FIND("_",P29)),LEN(RIGHT(P29,LEN(P29)-FIND("_",P29)))-FIND("_",RIGHT(P29,LEN(P29)-FIND("_",P29)))) -> Medium | T29: =RIGHT(P29,LEN(P29)-FIND("_",P29,FIND("_",P29)+1)) -> Medium | U29: =MID(P29,FIND("_",P29,FIND("_",P29)+1)+1,LEN(P29)-FIND("_",P29,FIND("_",P29)+1)) -> Medium
A30: 5 | B30: 43934 | C30: 16 | D30: 4 | E30: 1 | F30: 0 | G30: 400 | H30: 1200 | I30: 4000 | J30: 12000 | K30: =C30 * G30 + D30 * H30 + E30 * I30 + F30 * J30 -> 15200 | L30: =SUM(K30:K35) -> 104400 | M30: Golden trout | N30: 15000 | O30: Ultra | P30: =M30 & "_" & N30 & "_" & O30 -> Golden trout_15000_Ultra | Q30: =LEFT(RIGHT(P30,LEN(P30)-FIND("_",P30)),FIND("_",RIGHT(P30,LEN(P30)-FIND("_",P30)))-1) -> 15000 | R30: =MID(P30, FIND("_", P30)+1, FIND("_", P30, FIND("_", P30)+1) - FIND("_", P30)-1) -> 15000 | S30: =RIGHT(RIGHT(P30,LEN(P30)-FIND("_",P30)),LEN(RIGHT(P30,LEN(P30)-FIND("_",P30)))-FIND("_",RIGHT(P30,LEN(P30)-FIND("_",P30)))) -> Ultra | T30: =RIGHT(P30,LEN(P30)-FIND("_",P30,FIND("_",P30)+1)) -> Ultra | U30: =MID(P30,FIND("_",P30,FIND("_",P30)+1)+1,LEN(P30)-FIND("_",P30,FIND("_",P30)+1)) -> Ultra
A31: 5 | B31: 43935 | C31: 15 | D31: 5 | E31: 1 | F31: 0 | G31: 400 | H31: 1200 | I31: 4000 | J31: 12000 | K31: =C31 * G31 + D31 * H31 + E31 * I31 + F31 * J31 -> 16000 | M31: Stringfish | N31: 15000 | O31: Ultra | P31: =M31 & "_" & N31 & "_" & O31 -> Stringfish_15000_Ultra | Q31: =LEFT(RIGHT(P31,LEN(P31)-FIND("_",P31)),FIND("_",RIGHT(P31,LEN(P31)-FIND("_",P31)))-1) -> 15000 | R31: =MID(P31, FIND("_", P31)+1, FIND("_", P31, FIND("_", P31)+1) - FIND("_", P31)-1) -> 15000 | S31: =RIGHT(RIGHT(P31,LEN(P31)-FIND("_",P31)),LEN(RIGHT(P31,LEN(P31)-FIND("_",P31)))-FIND("_",RIGHT(P31,LEN(P31)-FIND("_",P31)))) -> Ultra | T31: =RIGHT(P31,LEN(P31)-FIND("_",P31,FIND("_",P31)+1)) -> Ultra | U31: =MID(P31,FIND("_",P31,FIND("_",P31)+1)+1,LEN(P31)-FIND("_",P31,FIND("_",P31)+1)) -> Ultra
A32: 5 | B32: 43936 | C32: 17 | D32: 3 | E32: 1 | F32: 0 | G32: 400 | H32: 1200 | I32: 4000 | J32: 12000 | K32: =C32 * G32 + D32 * H32 + E32 * I32 + F32 * J32 -> 14400 | M32: Salmon | N32: 700 | O32: Low | P32: =M32 & "_" & N32 & "_" & O32 -> Salmon_700_Low | Q32: =LEFT(RIGHT(P32,LEN(P32)-FIND("_",P32)),FIND("_",RIGHT(P32,LEN(P32)-FIND("_",P32)))-1) -> 700 | R32: =MID(P32, FIND("_", P32)+1, FIND("_", P32, FIND("_", P32)+1) - FIND("_", P32)-1) -> 700 | S32: =RIGHT(RIGHT(P32,LEN(P32)-FIND("_",P32)),LEN(RIGHT(P32,LEN(P32)-FIND("_",P32)))-FIND("_",RIGHT(P32,LEN(P32)-FIND("_",P32)))) -> Low | T32: =RIGHT(P32,LEN(P32)-FIND("_",P32,FIND("_",P32)+1)) -> Low | U32: =MID(P32,FIND("_",P32,FIND("_",P32)+1)+1,LEN(P32)-FIND("_",P32,FIND("_",P32)+1)) -> Low
A33: 5 | B33: 43937 | C33: 16 | D33: 4 | E33: 1 | F33: 0 | G33: 400 | H33: 1200 | I33: 4000 | J33: 12000 | K33: =C33 * G33 + D33 * H33 + E33 * I33 + F33 * J33 -> 15200 | M33: King salmon | N33: 1800 | O33: Medium | P33: =M33 & "_" & N33 & "_" & O33 -> King salmon_1800_Medium | Q33: =LEFT(RIGHT(P33,LEN(P33)-FIND("_",P33)),FIND("_",RIGHT(P33,LEN(P33)-FIND("_",P33)))-1) -> 1800 | R33: =MID(P33, FIND("_", P33)+1, FIND("_", P33, FIND("_", P33)+1) - FIND("_", P33)-1) -> 1800 | S33: =RIGHT(RIGHT(P33,LEN(P33)-FIND("_",P33)),LEN(RIGHT(P33,LEN(P33)-FIND("_",P33)))-FIND("_",RIGHT(P33,LEN(P33)-FIND("_",P33)))) -> Medium | T33: =RIGHT(P33,LEN(P33)-FIND("_",P33,FIND("_",P33)+1)) -> Medium | U33: =MID(P33,FIND("_",P33,FIND("_",P33)+1)+1,LEN(P33)-FIND("_",P33,FIND("_",P33)+1)) -> Medium
A34: 5 | B34: 43938 | C34: 14 | D34: 6 | E34: 1 | F34: 0 | G34: 400 | H34: 1200 | I34: 4000 | J34: 12000 | K34: =C34 * G34 + D34 * H34 + E34 * I34 + F34 * J34 -> 16800 | M34: Mitten crab | N34: 2000 | O34: Medium | P34: =M34 & "_" & N34 & "_" & O34 -> Mitten crab_2000_Medium | Q34: =LEFT(RIGHT(P34,LEN(P34)-FIND("_",P34)),FIND("_",RIGHT(P34,LEN(P34)-FIND("_",P34)))-1) -> 2000 | R34: =MID(P34, FIND("_", P34)+1, FIND("_", P34, FIND("_", P34)+1) - FIND("_", P34)-1) -> 2000 | S34: =RIGHT(RIGHT(P34,LEN(P34)-FIND("_",P34)),LEN(RIGHT(P34,LEN(P34)-FIND("_",P34)))-FIND("_",RIGHT(P34,LEN(P34)-FIND("_",P34)))) -> Medium | T34: =RIGHT(P34,LEN(P34)-FIND("_",P34,FIND("_",P34)+1)) -> Medium | U34: =MID(P34,FIND("_",P34,FIND("_",P34)+1)+1,LEN(P34)-FIND("_",P34,FIND("_",P34)+1)) -> Medium
A35: 5 | B35: 43939 | C35: 15 | D35: 4 | E35: 1 | F35: 1 | G35: 400 | H35: 1200 | I35: 4000 | J35: 12000 | K35: =C35 * G35 + D35 * H35 + E35 * I35 + F35 * J35 -> 26800 | M35: Guppy | N35: 1300 | O35: Medium | P35: =M35 & "_" & N35 & "_" & O35 -> Guppy_1300_Medium | Q35: =LEFT(RIGHT(P35,LEN(P35)-FIND("_",P35)),FIND("_",RIGHT(P35,LEN(P35)-FIND("_",P35)))-1) -> 1300 | R35: =MID(P35, FIND("_", P35)+1, FIND("_", P35, FIND("_", P35)+1) - FIND("_", P35)-1) -> 1300 | S35: =RIGHT(RIGHT(P35,LEN(P35)-FIND("_",P35)),LEN(RIGHT(P35,LEN(P35)-FIND("_",P35)))-FIND("_",RIGHT(P35,LEN(P35)-FIND("_",P35)))) -> Medium | T35: =RIGHT(P35,LEN(P35)-FIND("_",P35,FIND("_",P35)+1)) -> Medium | U35: =MID(P35,FIND("_",P35,FIND("_",P35)+1)+1,LEN(P35)-FIND("_",P35,FIND("_",P35)+1)) -> Medium
M36: Nibble fish | N36: 1500 | O36: Medium | P36: =M36 & "_" & N36 & "_" & O36 -> Nibble fish_1500_Medium | Q36: =LEFT(RIGHT(P36,LEN(P36)-FIND("_",P36)),FIND("_",RIGHT(P36,LEN(P36)-FIND("_",P36)))-1) -> 1500 | R36: =MID(P36, FIND("_", P36)+1, FIND("_", P36, FIND("_", P36)+1) - FIND("_", P36)-1) -> 1500 | S36: =RIGHT(RIGHT(P36,LEN(P36)-FIND("_",P36)),LEN(RIGHT(P36,LEN(P36)-FIND("_",P36)))-FIND("_",RIGHT(P36,LEN(P36)-FIND("_",P36)))) -> Medium | T36: =RIGHT(P36,LEN(P36)-FIND("_",P36,FIND("_",P36)+1)) -> Medium | U36: =MID(P36,FIND("_",P36,FIND("_",P36)+1)+1,LEN(P36)-FIND("_",P36,FIND("_",P36)+1)) -> Medium
A37: 6 | B37: 43941 | C37: 16 | D37: 4 | E37: 1 | F37: 0 | G37: 400 | H37: 1200 | I37: 4000 | J37: 12000 | K37: =C37 * G37 + D37 * H37 + E37 * I37 + F37 * J37 -> 15200 | L37: =SUM(K37:K42) -> 92400 | M37: Angelfish | N37: 3000 | O37: Medium | P37: =M37 & "_" & N37 & "_" & O37 -> Angelfish_3000_Medium | Q37: =LEFT(RIGHT(P37,LEN(P37)-FIND("_",P37)),FIND("_",RIGHT(P37,LEN(P37)-FIND("_",P37)))-1) -> 3000 | R37: =MID(P37, FIND("_", P37)+1, FIND("_", P37, FIND("_", P37)+1) - FIND("_", P37)-1) -> 3000 | S37: =RIGHT(RIGHT(P37,LEN(P37)-FIND("_",P37)),LEN(RIGHT(P37,LEN(P37)-FIND("_",P37)))-FIND("_",RIGHT(P37,LEN(P37)-FIND("_",P37)))) -> Medium | T37: =RIGHT(P37,LEN(P37)-FIND("_",P37,FIND("_",P37)+1)) -> Medium | U37: =MID(P37,FIND("_",P37,FIND("_",P37)+1)+1,LEN(P37)-FIND("_",P37,FIND("_",P37)+1)) -> Medium
A38: 6 | B38: 43942 | C38: 15 | D38: 5 | E38: 1 | F38: 0 | G38: 400 | H38: 1200 | I38: 4000 | J38: 12000 | K38: =C38 * G38 + D38 * H38 + E38 * I38 + F38 * J38 -> 16000 | M38: Betta | N38: 2500 | O38: Medium | P38: =M38 & "_" & N38 & "_" & O38 -> Betta_2500_Medium | Q38: =LEFT(RIGHT(P38,LEN(P38)-FIND("_",P38)),FIND("_",RIGHT(P38,LEN(P38)-FIND("_",P38)))-1) -> 2500 | R38: =MID(P38, FIND("_", P38)+1, FIND("_", P38, FIND("_", P38)+1) - FIND("_", P38)-1) -> 2500 | S38: =RIGHT(RIGHT(P38,LEN(P38)-FIND("_",P38)),LEN(RIGHT(P38,LEN(P38)-FIND("_",P38)))-FIND("_",RIGHT(P38,LEN(P38)-FIND("_",P38)))) -> Medium | T38: =RIGHT(P38,LEN(P38)-FIND("_",P38,FIND("_",P38)+1)) -> Medium | U38: =MID(P38,FIND("_",P38,FIND("_",P38)+1)+1,LEN(P38)-FIND("_",P38,FIND("_",P38)+1)) -> Medium
A39: 6 | B39: 43943 | C39: 17 | D39: 3 | E39: 1 | F39: 0 | G39: 400 | H39: 1200 | I39: 4000 | J39: 12000 | K39: =C39 * G39 + D39 * H39 + E39 * I39 + F39 * J39 -> 14400 | M39: Neon tetra | N39: 500 | O39: Low | P39: =M39 & "_" & N39 & "_" & O39 -> Neon tetra_500_Low | Q39: =LEFT(RIGHT(P39,LEN(P39)-FIND("_",P39)),FIND("_",RIGHT(P39,LEN(P39)-FIND("_",P39)))-1) -> 500 | R39: =MID(P39, FIND("_", P39)+1, FIND("_", P39, FIND("_", P39)+1) - FIND("_", P39)-1) -> 500 | S39: =RIGHT(RIGHT(P39,LEN(P39)-FIND("_",P39)),LEN(RIGHT(P39,LEN(P39)-FIND("_",P39)))-FIND("_",RIGHT(P39,LEN(P39)-FIND("_",P39)))) -> Low | T39: =RIGHT(P39,LEN(P39)-FIND("_",P39,FIND("_",P39)+1)) -> Low | U39: =MID(P39,FIND("_",P39,FIND("_",P39)+1)+1,LEN(P39)-FIND("_",P39,FIND("_",P39)+1)) -> Low
A40: 6 | B40: 43944 | C40: 16 | D40: 4 | E40: 1 | F40: 0 | G40: 400 | H40: 1200 | I40: 4000 | J40: 12000 | K40: =C40 * G40 + D40 * H40 + E40 * I40 + F40 * J40 -> 15200 | M40: Rainbowfish | N40: 800 | O40: Low | P40: =M40 & "_" & N40 & "_" & O40 -> Rainbowfish_800_Low | Q40: =LEFT(RIGHT(P40,LEN(P40)-FIND("_",P40)),FIND("_",RIGHT(P40,LEN(P40)-FIND("_",P40)))-1) -> 800 | R40: =MID(P40, FIND("_", P40)+1, FIND("_", P40, FIND("_", P40)+1) - FIND("_", P40)-1) -> 800 | S40: =RIGHT(RIGHT(P40,LEN(P40)-FIND("_",P40)),LEN(RIGHT(P40,LEN(P40)-FIND("_",P40)))-FIND("_",RIGHT(P40,LEN(P40)-FIND("_",P40)))) -> Low | T40: =RIGHT(P40,LEN(P40)-FIND("_",P40,FIND("_",P40)+1)) -> Low | U40: =MID(P40,FIND("_",P40,FIND("_",P40)+1)+1,LEN(P40)-FIND("_",P40,FIND("_",P40)+1)) -> Low
...

Sheet Sum_Together
A1: Week | B1: Turnip_SubTotal | C1: Fishing_SubTotal | D1: Total_Week_Profit | E1: V_Lookup #1
A2: 1 | B2: =SUMIF(Turnip!A2:A84, A2, Turnip!J2:J79) -> 15000 | C2: =SUMIF(Deep_Sea_Creature!A2:A84, A2, Deep_Sea_Creature!L2:L79) /3 -> 32133.333 | D2: =B2 + C2 -> 47133.333 | G2: SUMIF(range, criteria, sum_range)
A3: 2 | B3: =SUMIF(Turnip!A3:A85, A3, Turnip!J3:J80) -> -4000 | C3: =SUMIF(Deep_Sea_Creature!A3:A85, A3, Deep_Sea_Creature!L3:L80) /3 -> 34800 | D3: =B3 + C3 -> 30800
A4: 3 | B4: =SUMIF(Turnip!A4:A86, A4, Turnip!J4:J81) -> 143000 | C4: =SUMIF(Deep_Sea_Creature!A4:A86, A4, Deep_Sea_Creature!L4:L81) /3 -> 32133.333 | D4: =B4 + C4 -> 175133.33
A5: 4 | B5: =SUMIF(Turnip!A5:A87, A5, Turnip!J5:J82) -> 460000 | C5: =SUMIF(Deep_Sea_Creature!A5:A87, A5, Deep_Sea_Creature!L5:L82) /3 -> 32133.333 | D5: =B5 + C5 -> 492133.33
A6: 5 | B6: =SUMIF(Turnip!A6:A88, A6, Turnip!J6:J83) -> 15000 | C6: =SUMIF(Deep_Sea_Creature!A6:A88, A6, Deep_Sea_Creature!L6:L83) /3 -> 34800 | D6: =B6 + C6 -> 49800
A7: 6 | B7: =SUMIF(Turnip!A7:A89, A7, Turnip!J7:J84) -> -5000 | C7: =SUMIF(Deep_Sea_Creature!A7:A89, A7, Deep_Sea_Creature!L7:L84) /3 -> 30800 | D7: =B7 + C7 -> 25800
A8: 7 | B8: =SUMIF(Turnip!A8:A90, A8, Turnip!J8:J85) -> 324000 | C8: =SUMIF(Deep_Sea_Creature!A8:A90, A8, Deep_Sea_Creature!L8:L85) /3 -> 32133.333 | D8: =B8 + C8 -> 356133.33
A9: 8 | B9: =SUMIF(Turnip!A9:A91, A9, Turnip!J9:J86) -> 2000 | C9: =SUMIF(Deep_Sea_Creature!A9:A91, A9, Deep_Sea_Creature!L9:L86) /3 -> 34800 | D9: =B9 + C9 -> 36800
A10: 9 | B10: =SUMIF(Turnip!A10:A92, A10, Turnip!J10:J87) -> 409000 | C10: =SUMIF(Deep_Sea_Creature!A10:A92, A10, Deep_Sea_Creature!L10:L87) /3 -> 30800 | D10: =B10 + C10 -> 439800
A11: 10 | B11: =SUMIF(Turnip!A11:A93, A11, Turnip!J11:J88) -> -4000 | C11: =SUMIF(Deep_Sea_Creature!A11:A93, A11, Deep_Sea_Creature!L11:L88) /3 -> 32133.333 | D11: =B11 + C11 -> 28133.333
A12: 11 | B12: =SUMIF(Turnip!A12:A94, A12, Turnip!J12:J89) -> 381000 | C12: =SUMIF(Deep_Sea_Creature!A12:A94, A12, Deep_Sea_Creature!L12:L89) /3 -> 34800 | D12: =B12 + C12 -> 415800
A13: 12 | B13: =SUMIF(Turnip!A13:A95, A13, Turnip!J13:J90) -> -3000 | C13: =SUMIF(Deep_Sea_Creature!A13:A95, A13, Deep_Sea_Creature!L13:L90) /3 -> 30800 | D13: =B13 + C13 -> 27800
